---
date: "2008-04-03"
title: Try-catch flutuante
tags: [ "code" ]
---
Esse detalhe da linguagem quem me fez descobrir foi o **Yorick**, que [costuma comentar](http://www.caloni.com.br/quando-o-ponteiro-nulo-nao-e-invalido#comment-345) no blogue e tive o prazer de conhecer no [4o. EPA-CCPP](http://www.caloni.com.br/blog/epa-ccpp-4-nossa-comunidade-ganhando-forma).

É possível, apesar de bizarro, colocar um bloco try-catch em torno da lista de inicialização de variáveis de um construtor. Essa característica da linguagem permite que possamos capturar alguma exceção lançada por algum construtor de algum membro da classe. A construção em código ficaria no estilo abaixo:

    
    Class::Class() try : initialization-list
    {
        // Class constructor body
    }
    catch(...) // note: this IS right!
    {
        // do something about
        // just like "throw" over here
    }

Apesar dessa capacidade, não conseguimos parar o lançamento da exceção. Após seu lançamento, caímos no bloco catch abaixo do corpo do construtor e a exceção é lançada novamente, como se houvesse uma intrução throw no final do catch.

O exemplo abaixo demonstra um código de uma classe que captura a exceção durante a inicialização dos membros. Na seguida o catch da função main é executada, provando que a exceção de fato não é "salva" no primeiro bloco.

```cpp
#include <iostream>

/* This class explodes */
class Explode
{
	public:
		Explode(int x) 
		{
			m_x = x;
			throw x;
		}

		void print()
		{
			std::cout << "The number: " << m_x << std::endl;
		}

	private:
		int m_x;
};

/* This class is going to be exploded */
class Victim
{
	public:
		Victim() try : m_explode(5)
		{
			std::cout << "You're supposed to NOT seeing this...\n";
		}
		catch(...) 
		{ 
			std::cerr << "Something BAD hapenned\n";
			std::cerr << "We're going to blow up\n";
			// just like 'throw' over here
		}

		void print()
		{
			m_explode.print();
		}

	private:
		Explode m_explode;
};

int main()
{
	try
	{
		Victim vic;
	}
	catch(...)
	{
		std::cerr << "Something BAD BAD happenned...\n";
	}
}

 

```

Testei esse código nos seguintes compiladores:

    
  * Visual Studio 6. Falhou, demonstrando desconhecer a sintaxe.

    
  * Borland C++ Builder 5. Falhou, demonstrando desconhecer a sintaxe.

    
  * Borland Developer Studio 4. Falhou, com o mesmo erro.

    
  * Visual Studio 2003. Comportamento esperado.

    
  * Visual Studio 2005. Comportamento esperado.

    
  * Visual Studio 2008. Comportamento esperado.

    
  * G++ (no Cygwin). Comportamento esperado.

A saída esperada é a seguinte:

    
    Something BAD hapenned
    We're going to blow up
    Something BAD BAD happenned...
